[2024-11-12T13:26:32.350+0000] {local_task_job_runner.py:123} INFO - ::group::Pre task execution logs
[2024-11-12T13:26:32.360+0000] {taskinstance.py:2613} INFO - Dependencies all met for dep_context=non-requeueable deps ti=<TaskInstance: git_repo_dag.list_repo_tags manual__2024-11-12T13:26:26.245439+00:00 [queued]>
[2024-11-12T13:26:32.367+0000] {taskinstance.py:2613} INFO - Dependencies all met for dep_context=requeueable deps ti=<TaskInstance: git_repo_dag.list_repo_tags manual__2024-11-12T13:26:26.245439+00:00 [queued]>
[2024-11-12T13:26:32.367+0000] {taskinstance.py:2866} INFO - Starting attempt 1 of 1
[2024-11-12T13:26:32.392+0000] {taskinstance.py:2889} INFO - Executing <Task(GithubOperator): list_repo_tags> on 2024-11-12 13:26:26.245439+00:00
[2024-11-12T13:26:32.408+0000] {standard_task_runner.py:104} INFO - Running: ['airflow', 'tasks', 'run', 'git_repo_dag', 'list_repo_tags', 'manual__2024-11-12T13:26:26.245439+00:00', '--job-id', '28', '--raw', '--subdir', 'DAGS_FOLDER/git_repo_dag.py', '--cfg-path', '/tmp/tmpj_7bufuc']
[2024-11-12T13:26:32.410+0000] {logging_mixin.py:190} WARNING - /home/airflow/.local/lib/python3.12/site-packages/airflow/task/task_runner/standard_task_runner.py:70 DeprecationWarning: This process (pid=101) is multi-threaded, use of fork() may lead to deadlocks in the child.
[2024-11-12T13:26:32.412+0000] {standard_task_runner.py:105} INFO - Job 28: Subtask list_repo_tags
[2024-11-12T13:26:32.412+0000] {standard_task_runner.py:72} INFO - Started process 115 to run task
[2024-11-12T13:26:32.506+0000] {task_command.py:467} INFO - Running <TaskInstance: git_repo_dag.list_repo_tags manual__2024-11-12T13:26:26.245439+00:00 [running]> on host 12040030fca5
[2024-11-12T13:26:32.616+0000] {taskinstance.py:3132} INFO - Exporting env vars: AIRFLOW_CTX_DAG_OWNER='airflow' AIRFLOW_CTX_DAG_ID='git_repo_dag' AIRFLOW_CTX_TASK_ID='list_repo_tags' AIRFLOW_CTX_EXECUTION_DATE='2024-11-12T13:26:26.245439+00:00' AIRFLOW_CTX_TRY_NUMBER='1' AIRFLOW_CTX_DAG_RUN_ID='manual__2024-11-12T13:26:26.245439+00:00'
[2024-11-12T13:26:32.617+0000] {taskinstance.py:731} INFO - ::endgroup::
[2024-11-12T13:26:32.688+0000] {taskinstance.py:3311} ERROR - Task failed with exception
Traceback (most recent call last):
  File "/home/airflow/.local/lib/python3.12/site-packages/airflow/providers/github/operators/github.py", line 68, in execute
    hook = GithubHook(github_conn_id=self.github_conn_id)
           ^^^^^^^^^^^^^^^^^^^^^^^^^^^^^^^^^^^^^^^^^^^^^^
  File "/home/airflow/.local/lib/python3.12/site-packages/airflow/providers/github/hooks/github.py", line 48, in __init__
    self.get_conn()
  File "/home/airflow/.local/lib/python3.12/site-packages/airflow/providers/github/hooks/github.py", line 55, in get_conn
    conn = self.get_connection(self.github_conn_id)
           ^^^^^^^^^^^^^^^^^^^^^^^^^^^^^^^^^^^^^^^^
  File "/home/airflow/.local/lib/python3.12/site-packages/airflow/hooks/base.py", line 83, in get_connection
    conn = Connection.get_connection_from_secrets(conn_id)
           ^^^^^^^^^^^^^^^^^^^^^^^^^^^^^^^^^^^^^^^^^^^^^^^
  File "/home/airflow/.local/lib/python3.12/site-packages/airflow/models/connection.py", line 537, in get_connection_from_secrets
    raise AirflowNotFoundException(f"The conn_id `{conn_id}` isn't defined")
airflow.exceptions.AirflowNotFoundException: The conn_id `github_default` isn't defined

During handling of the above exception, another exception occurred:

Traceback (most recent call last):
  File "/home/airflow/.local/lib/python3.12/site-packages/airflow/models/taskinstance.py", line 767, in _execute_task
    result = _execute_callable(context=context, **execute_callable_kwargs)
             ^^^^^^^^^^^^^^^^^^^^^^^^^^^^^^^^^^^^^^^^^^^^^^^^^^^^^^^^^^^^^
  File "/home/airflow/.local/lib/python3.12/site-packages/airflow/models/taskinstance.py", line 733, in _execute_callable
    return ExecutionCallableRunner(
           ^^^^^^^^^^^^^^^^^^^^^^^^
  File "/home/airflow/.local/lib/python3.12/site-packages/airflow/utils/operator_helpers.py", line 252, in run
    return self.func(*args, **kwargs)
           ^^^^^^^^^^^^^^^^^^^^^^^^^^
  File "/home/airflow/.local/lib/python3.12/site-packages/airflow/models/baseoperator.py", line 417, in wrapper
    return func(self, *args, **kwargs)
           ^^^^^^^^^^^^^^^^^^^^^^^^^^^
  File "/home/airflow/.local/lib/python3.12/site-packages/airflow/providers/github/operators/github.py", line 80, in execute
    raise AirflowException(f"GitHub operator error: {e}")
airflow.exceptions.AirflowException: GitHub operator error: The conn_id `github_default` isn't defined
[2024-11-12T13:26:32.703+0000] {taskinstance.py:1225} INFO - Marking task as FAILED. dag_id=git_repo_dag, task_id=list_repo_tags, run_id=manual__2024-11-12T13:26:26.245439+00:00, execution_date=20241112T132626, start_date=20241112T132632, end_date=20241112T132632
[2024-11-12T13:26:32.727+0000] {taskinstance.py:340} INFO - ::group::Post task execution logs
[2024-11-12T13:26:32.727+0000] {standard_task_runner.py:124} ERROR - Failed to execute job 28 for task list_repo_tags (GitHub operator error: The conn_id `github_default` isn't defined; 115)
Traceback (most recent call last):
  File "/home/airflow/.local/lib/python3.12/site-packages/airflow/providers/github/operators/github.py", line 68, in execute
    hook = GithubHook(github_conn_id=self.github_conn_id)
           ^^^^^^^^^^^^^^^^^^^^^^^^^^^^^^^^^^^^^^^^^^^^^^
  File "/home/airflow/.local/lib/python3.12/site-packages/airflow/providers/github/hooks/github.py", line 48, in __init__
    self.get_conn()
  File "/home/airflow/.local/lib/python3.12/site-packages/airflow/providers/github/hooks/github.py", line 55, in get_conn
    conn = self.get_connection(self.github_conn_id)
           ^^^^^^^^^^^^^^^^^^^^^^^^^^^^^^^^^^^^^^^^
  File "/home/airflow/.local/lib/python3.12/site-packages/airflow/hooks/base.py", line 83, in get_connection
    conn = Connection.get_connection_from_secrets(conn_id)
           ^^^^^^^^^^^^^^^^^^^^^^^^^^^^^^^^^^^^^^^^^^^^^^^
  File "/home/airflow/.local/lib/python3.12/site-packages/airflow/models/connection.py", line 537, in get_connection_from_secrets
    raise AirflowNotFoundException(f"The conn_id `{conn_id}` isn't defined")
airflow.exceptions.AirflowNotFoundException: The conn_id `github_default` isn't defined

During handling of the above exception, another exception occurred:

Traceback (most recent call last):
  File "/home/airflow/.local/lib/python3.12/site-packages/airflow/task/task_runner/standard_task_runner.py", line 117, in _start_by_fork
    ret = args.func(args, dag=self.dag)
          ^^^^^^^^^^^^^^^^^^^^^^^^^^^^^
  File "/home/airflow/.local/lib/python3.12/site-packages/airflow/cli/cli_config.py", line 49, in command
    return func(*args, **kwargs)
           ^^^^^^^^^^^^^^^^^^^^^
  File "/home/airflow/.local/lib/python3.12/site-packages/airflow/utils/cli.py", line 116, in wrapper
    return f(*args, **kwargs)
           ^^^^^^^^^^^^^^^^^^
  File "/home/airflow/.local/lib/python3.12/site-packages/airflow/cli/commands/task_command.py", line 483, in task_run
    task_return_code = _run_task_by_selected_method(args, _dag, ti)
                       ^^^^^^^^^^^^^^^^^^^^^^^^^^^^^^^^^^^^^^^^^^^^
  File "/home/airflow/.local/lib/python3.12/site-packages/airflow/cli/commands/task_command.py", line 256, in _run_task_by_selected_method
    return _run_raw_task(args, ti)
           ^^^^^^^^^^^^^^^^^^^^^^^
  File "/home/airflow/.local/lib/python3.12/site-packages/airflow/cli/commands/task_command.py", line 341, in _run_raw_task
    return ti._run_raw_task(
           ^^^^^^^^^^^^^^^^^
  File "/home/airflow/.local/lib/python3.12/site-packages/airflow/utils/session.py", line 97, in wrapper
    return func(*args, session=session, **kwargs)
           ^^^^^^^^^^^^^^^^^^^^^^^^^^^^^^^^^^^^^^
  File "/home/airflow/.local/lib/python3.12/site-packages/airflow/models/taskinstance.py", line 3005, in _run_raw_task
    return _run_raw_task(
           ^^^^^^^^^^^^^^
  File "/home/airflow/.local/lib/python3.12/site-packages/airflow/models/taskinstance.py", line 273, in _run_raw_task
    TaskInstance._execute_task_with_callbacks(
  File "/home/airflow/.local/lib/python3.12/site-packages/airflow/models/taskinstance.py", line 3159, in _execute_task_with_callbacks
    result = self._execute_task(context, task_orig)
             ^^^^^^^^^^^^^^^^^^^^^^^^^^^^^^^^^^^^^^
  File "/home/airflow/.local/lib/python3.12/site-packages/airflow/models/taskinstance.py", line 3183, in _execute_task
    return _execute_task(self, context, task_orig)
           ^^^^^^^^^^^^^^^^^^^^^^^^^^^^^^^^^^^^^^^
  File "/home/airflow/.local/lib/python3.12/site-packages/airflow/models/taskinstance.py", line 767, in _execute_task
    result = _execute_callable(context=context, **execute_callable_kwargs)
             ^^^^^^^^^^^^^^^^^^^^^^^^^^^^^^^^^^^^^^^^^^^^^^^^^^^^^^^^^^^^^
  File "/home/airflow/.local/lib/python3.12/site-packages/airflow/models/taskinstance.py", line 733, in _execute_callable
    return ExecutionCallableRunner(
           ^^^^^^^^^^^^^^^^^^^^^^^^
  File "/home/airflow/.local/lib/python3.12/site-packages/airflow/utils/operator_helpers.py", line 252, in run
    return self.func(*args, **kwargs)
           ^^^^^^^^^^^^^^^^^^^^^^^^^^
  File "/home/airflow/.local/lib/python3.12/site-packages/airflow/models/baseoperator.py", line 417, in wrapper
    return func(self, *args, **kwargs)
           ^^^^^^^^^^^^^^^^^^^^^^^^^^^
  File "/home/airflow/.local/lib/python3.12/site-packages/airflow/providers/github/operators/github.py", line 80, in execute
    raise AirflowException(f"GitHub operator error: {e}")
airflow.exceptions.AirflowException: GitHub operator error: The conn_id `github_default` isn't defined
[2024-11-12T13:26:32.748+0000] {local_task_job_runner.py:266} INFO - Task exited with return code 1
[2024-11-12T13:26:32.765+0000] {taskinstance.py:3895} INFO - 0 downstream tasks scheduled from follow-on schedule check
[2024-11-12T13:26:32.779+0000] {local_task_job_runner.py:245} INFO - ::endgroup::
